Workbook

Sheet JuriKurumici
A1: Adı-Soyadı | B1: Akademik Ünvan | C1: Fakülte (Kadrosu) | D1: Bölüm (Kadrosu)
A2: Abdullah Burak POLAT | B2: Prof.Dr. | C2: ELEKTRİK- ELEK. FAKÜLTESİ | D2: ELEK. VE HAB.MÜH.BÖL
A3: Abdurrahman Kamuran KADIPAŞAOĞLU | B3: Doç.Dr. | C3: ELEKTRİK- ELEK. FAKÜLTESİ | D3: BİYOMEDİKAL MÜH.
A4: Abdürrezzak Emin BOZDOĞAN | B4: Prof.Dr. | C4: FEN-EDEBİYAT FAKÜLTESİ | D4: KİMYA
A5: Adem BAKKALOĞLU | B5: Prof.Dr. | C5: KİMYA-METALURJİ FAKÜLTESİ | D5: MET.VE MALZEME MÜH.BÖL.
A6: Adem Cengiz ÇEVİKEL | B6: Doç.Dr. | C6: EĞİTİM FAKÜLTESİ | D6: MATEMATİK VE FEN BİLİMLERİ EĞİTİMİ
A7: Afife Binnaz HAZAR | B7: Prof.Dr. | C7: KİMYA-METALURJİ FAKÜLTESİ | D7: MET.VE MALZEME MÜH.BÖL.
A8: Ahmet KOYUN | B8: Prof.Dr. | C8: MAKİNE FAKÜLTESİ | D8: MEKATRONİK MÜH.
A9: Ahmet ÖZDEŞ | B9: Öğr.Gör. Dr. | C9: ELEKTRİK- ELEK. FAKÜLTESİ | D9: ELEKTRİK MÜH.
A10: Ahmet SAĞIN | B10: Dr.Öğr.Üyesi | C10: KİMYA-METALURJİ FAKÜLTESİ | D10: MET.VE MALZEME MÜH.BÖL.
A11: Ahmet ÇELİK | B11: Dr.Öğr.Üyesi | C11: MAKİNE FAKÜLTESİ | D11: MAKİNE MÜH.
A12: Ahmet DEMİR | B12: Prof.Dr. | C12: İNŞAAT FAKÜLTESİ | D12: ÇEVRE MÜH.
... A782: Zühal TURGUT | B782: Prof.Dr. | C782: FEN-EDEBİYAT FAKÜLTESİ | D782: KİMYA

Sheet BasvuruListesi
A1: OgrenciNo | B1: OgrenimTipAdi | C1: AnabilimdaliAdi | D1: ProgramAdi | E1: Tez Başlığı | F1: AdSoyad | G1: TcPasaPortNo | H1: EMail | I1: CepTel | J1: GsisKayitTarihi | K1: MezuniyetYayinKontrolDurumAdi | L1: TezDanismanAdi | M1: YayinSarti | N1: PatentSayisi | O1: ProjeSayisi | P1: UBildiriSayisi | Q1: UMakaleSayisi | R1: UABildiriSayisi | S1: UAMakaleSayisi
A2: 15549023 | B2: Tezli Yüksek Lisans | C2: Elektrik Müh. | D2: Elektrik Tesisleri | E2: Zaman Serileri Yöntemleri İle Yenilenebilir Enerji Kaynaklarının Güç Üretim Tahminlenmesi | F2: Feyza TURAN | G2: 53947181974 | H2: feyzaozcanf@gmail.com | I2: (0554) 322-2775 | J2: 42244 | K2: Kabul Edildi | L2: Dr. Öğr. Üyesi Bedri KEKEZOĞLU | M2: Var | N2: 0 | O2: 0 | P2: 0 | Q2: 0 | R2: 0 | S2: 1
A3: 8520017 | B3: Tezli Yüksek Lisans | C3: Kimya Müh. | D3: Kimya Müh. | E3: Gözenekli Hidrojel Sentezi Ve Karakterizasyonu | F3: Mustafa ÇANKAYA | G3: 27239610404 | H3: m.cankaya77@yahoo.com.tr | I3: (0555) 625-2356 | J3: 39710 | K3: Kabul Edildi | L3: Doç. Dr. OSMAN İSMAİL | M3: Yok | N3: 0 | O3: 0 | P3: 0 | Q3: 0 | R3: 0 | S3: 0
A4: 17520015 | B4: Tezli Yüksek Lisans | C4: Kimya Müh. | D4: Kimya Müh. | E4: Proton Geçirimli Membran Tipi Yakıt Hücrelerinde Gaz Difüzyon Tabakasının Modifikasyonu Ve Modellenmesi | F4: Şeyma KİL | G4: 13991419478 | H4: kseyma.94@gmail.com | I4: (0531) 962-3277 | J4: 42923 | K4: Kabul Edildi | L4: Prof. Dr. Hasan SADIKOĞLU | M4: Var | N4: 0 | O4: 0 | P4: 0 | Q4: 0 | R4: 1 | S4: 0
A5: 13552019 | B5: Tezli Yüksek Lisans | C5: Makine Müh. | D5: Makine Teorisi ve Kontrol | E5: Kinetik Enerji Geri Kazanım Sistemi Tasarımı | F5: Aykut DANA | G5: 53155731336 | H5: aykutdana@gmail.com | I5: (0545) 767-6739 | J5: 41682 | K5: Kabul Edildi | L5: Doç. Dr. CİHAN DEMİR | M5: Var | N5: 0 | O5: 0 | P5: 1 | Q5: 0 | R5: 0 | S5: 0
A6: 11550009 | B6: Tezli Yüksek Lisans | C6: Harita Müh. | D6: Uzaktan Algılama ve CBS | E6: Bım Modellerının Olusturulmasında Genellestırme Yaklasımlarının Uygulanması | F6: Serdar KAYA | G6: 26576508368 | H6: serdarr.kayaa@gmail.com | I6: (0507) 614-9461 | J6: 40806 | K6: Kabul Edildi | L6: Dr. Öğr. Üyesi Alper Şen | M6: Yok | N6: 0 | O6: 0 | P6: 0 | Q6: 0 | R6: 0 | S6: 0
A7: 17554034 | B7: Tezli Yüksek Lisans | C7: Biyomühendislik | D7: Biyomühendislik | E7: Grafen Oksit Temelli Nanokompozit Üretiminin Optimizasyonu Ve Fotokatalitik Antibakteriyel Aktivitesinin Araştırılması | F7: Gizem DEMİR | G7: 46897732242 | H7: gizemddemirr11@gmail.com | I7: (0531) 511-5314 | J7: 42926 | K7: Kabul Edildi | L7: Doç. Dr. CEM BÜLENT ÜSTÜNDAĞ | M7: Var | N7: 0 | O7: 0 | P7: 1 | Q7: 0 | R7: 0 | S7: 0
A8: 165A3005 | B8: Tezli Yüksek Lisans | C8: Fen Bil. ve Mat. Eğitimi - Fen Bilgisi Eğitimi | D8: Fen Bilgisi Eğitimi | E8: Cıddı Oyunların İlköğretım 5.Sınıf Öğrencılerın Fen Bılımlerı Dersıne Karşı Tutumlarına Etkısı | F8: Emine SENA TOPRAK YALLIHEP | G8: 24101483722 | H8: sntoprak@gmail.com | I8: (0507) 378-5676 | J8: 42584 | K8: Kabul Edildi | L8: Doç. Dr. Hakan AKÇAY | M8: Var | N8: 0 | O8: 0 | P8: 0 | Q8: 0 | R8: 1 | S8: 0
A9: 98532105 | B9: Tezli Yüksek Lisans | C9: Mimarlık | D9: Mimari Tasarım | E9: Alvaro Siza Mimarlığı | F9: İbrahim BAKIR | G9: 38599442598 | H9: ibrahimbakir@hotmail.com | I9: (0554) 348-5616 | J9: 40772 | K9: Taslak | L9: Doç. Dr. YASEMEN SAY ÖZER | M9: Yok | N9: 0 | O9: 0 | P9: 0 | Q9: 0 | R9: 0 | S9: 0
A10: 15567022 | B10: Tezli Yüksek Lisans | C10: Kontrol ve Otomasyon Müh. | D10: Kontrol ve Otomasyon Müh. | E10: Mobil Robotların Senkronizasyonu | F10: Abduljabbar ABDULJABBAR | G10: 99695317852 | H10: abduljabbarkhudhur@gmail.com | I10: (0537) 411-9588 | J10: 42265 | K10: Kabul Edildi | L10: Dr. Öğr. Üyesi Janset Dasdemir | M10: Var | N10: 0 | O10: 0 | P10: 0 | Q10: 0 | R10: 1 | S10: 0
A11: 13506010 | B11: Tezli Yüksek Lisans | C11: Endüstri Müh. | D11: Endüstri Müh. | E11: İşletmelerde Müşteri Deneyiminin Müşteri Sadakati Ve Hizmet Kalitesi İle İlişkisi | F11: Esra ERGİN | G11: 15202748582 | H11: esraergin@outlook.com | I11: (0543) 593-6642 | J11: 41460 | K11: Kabul Edildi | L11: Doç. Dr. Bahadır Gülsün | M11: Var | N11: 0 | O11: 0 | P11: 1 | Q11: 0 | R11: 0 | S11: 0
A12: 15561004 | B12: Tezli Yüksek Lisans | C12: Mimarlık | D12: Konut Üretimi ve Yapım Yönetimi | E12: Kamu Özel İş Birliği Yatırımlarına Ait Finansal Risklerin Tasarım Sürecinde Yönetimi (Kaynaşlı Kültür Merkezi Binası Örneği) | F12: Mahmuthan ÇAKIR | G12: 71335158452 | H12: mahmuthancakir@gmail.com | I12: (0532) 765-9403 | J12: 42181 | K12: Kabul Edildi | L12: Doç. Dr. SERHAT BAŞDOĞAN | M12: Var | N12: 0 | O12: 0 | P12: 1 | Q12: 0 | R12: 0 | S12: 0
A13: 17535003 | B13: Tezli Yüksek Lisans | C13: Mimarlık | D13: Yapı | E13: Açık Yeşil Alanların Kullanıcı Ve Çevre Açısından İrdelenmesi: Yahya Kemal (Serencebey) Parkı Örneği | F13: Özlem ERDOĞAN | G13: 49909396920 | H13: ozlem-erdogan94@hotmail.com | I13: (0538) 371-6292 | J13: 42923 | K13: Kabul Edildi | L13: Doç. Dr. M. Zafer AKDEMİR | M13: Var | N13: 0 | O13: 0 | P13: 1 | Q13: 0 | R13: 0 | S13: 0
A14: 16530004 | B14: Tezli Yüksek Lisans | C14: Mimarlık | D14: Bina Araştırma ve Planlama | E14: Olimpiyatların Kentsel Dönüşüm Üzerindeki Etkisi | F14: Merve ÇELİK | G14: 27148589396 | H14: mervecelikka@gmail.com | I14: (0531) 083-4348 | J14: 42583 | K14: Kabul Edildi | L14: Doç. Dr. Kunter Manisa | M14: Var | N14: 0 | O14: 0 | P14: 0 | Q14: 0 | R14: 1 | S14: 0
A15: 9504001 | B15: Tezli Yüksek Lisans | C15: Elektronik ve Haberleşme Müh. | D15: Elektronik | E15: Evrimsel Algoritmalar Kullanarak Analog Devre Tasarımı | F15: Tuğba SAATÇI AYTEN | G15: 28894708512 | H15: saatcitugba@yahoo.com | I15: (0505) 675-0497 | J15: 40079 | K15: Kabul Edildi | L15: Prof. Dr. Tülay YILDIRIM | M15: Yok | N15: 0 | O15: 0 | P15: 0 | Q15: 0 | R15: 0 | S15: 0
A16: 15535019 | B16: Tezli Yüksek Lisans | C16: Mimarlık | D16: Yapı | E16: Isı Ve Su Yalıtımı Uygulamaları Üzerine Bir Çalışma | F16: Hümeyra ŞENTÜRK | G16: 33277047980 | H16: humeyrasenturk@gmail.com | I16: (0555) 874-1874 | J16: 42395 | K16: Kabul Edildi | L16: Doç. Dr. Erkan AVLAR | M16: Var | N16: 0 | O16: 0 | P16: 1 | Q16: 0 | R16: 0 | S16: 0
A17: 15530010 | B17: Tezli Yüksek Lisans | C17: Mimarlık | D17: Bina Araştırma ve Planlama | E17: Mikroalgler Kullanılarak Tasarlanan Fotobiyoreaktör Sistemlerinin Mimari Tasarım Disiplinine Aktarılmasındaki Sorunlar | F17: Yunus TURAN PEKMEZCİ | G17: 21049712860 | H17: y.turanpekmezci@gmail.com | I17: (0554) 229-1038 | J17: 42188 | K17: Kabul Edildi | L17: Doç. Dr. Funda Öztürk Kerestecioğlu | M17: Var | N17: 0 | O17: 0 | P17: 0 | Q17: 0 | R17: 0 | S17: 1
A18: 16520005 | B18: Tezli Yüksek Lisans | C18: Kimya Müh. | D18: Kimya Müh. | E18: Farmakolojik Olarak Aktif Bileşenlerin Sentezi | F18: Canan ÇAVAŞ | G18: 58039599996 | H18: canancavass@gmail.com | I18: (0506) 884-8026 | J18: 42583 | K18: Kabul Edildi | L18: Doç. Dr. Elçin DEMİRHAN YILMAZ | M18: Var | N18: 0 | O18: 0 | P18: 1 | Q18: 0 | R18: 0 | S18: 0
A19: 12527004 | B19: Tezli Yüksek Lisans | C19: Metalürji ve Malzeme Müh. | D19: Malzeme | E19: Polimerik İmplant Kullanımında Karşılaşılan Problemlerin Yaratıcı Problem Çözme Teorisi İle Değerlendirilmesi | F19: Şerife ÖZTÜRK | G19: 56122586038 | H19: ozturk__serife@hotmail.com | I19: (0538) 322-2695 | J19: 41162 | K19: Kabul Edildi | L19: Doç. Dr. Cem AKÇA | M19: Yok | N19: 0 | O19: 0 | P19: 0 | Q19: 0 | R19: 0 | S19: 0
A20: 13507003 | B20: Doktora | C20: Fizik | D20: Fizik | E20: Bakterilerin (Escherichia Coli Ve Enterococcus Faecalis) Gözenekli Silisyum Yüzeyinde Depolanmasında Elektrik Alanın Etkisi | F20: Sevinç GÜLER | G20: 26416617946 | H20: sevinc7yildirim@gmail.com | I20: (0535) 729-8063 | J20: 41460 | K20: Kabul Edildi | L20: Doç. Dr. Çiğdem Oruç | M20: Var | N20: 0 | O20: 0 | P20: 0 | Q20: 0 | R20: 0 | S20: 1
A21: 15505043 | B21: Tezli Yüksek Lisans | C21: Elektronik ve Haberleşme Müh. | D21: Haberleşme | E21: 3 Boyutlu Uzayda Ve Kapalı Ortamlarda Bir Mobil Robotun Konum Ve Hedef Tespiti | F21: Ban İSAM RASHİD ALBAYATİ | G21: 99587331690 | H21: banmoon99@gmail.com | J21: 42285 | K21: Kabul Edildi | L21: Dr. Öğr. Üyesi serkan kurt | M21: Var | N21: 0 | O21: 0 | P21: 0 | Q21: 1 | R21: 0 | S21: 0
A22: 12504018 | B22: Tezli Yüksek Lisans | C22: Elektronik ve Haberleşme Müh. | D22: Elektronik | E22: Aktif Elamanlar İle Faz İlerlemeli, Gecikmeli Kompansatör Ve Kontrolör Devrelerinin Tasarımı | F22: Yusuf BUZCU | G22: 39094330922 | H22: yusufbuzcu@gmail.com | I22: (0507) 610-7727 | J22: 41164 | K22: Kabul Edildi | L22: Dr. Öğr. Üyesi Umut Engin AYTEN | M22: Yok | N22: 0 | O22: 0 | P22: 0 | Q22: 0 | R22: 0 | S22: 0
A23: 13554001 | B23: Tezli Yüksek Lisans | C23: Biyomühendislik | D23: Biyomühendislik | E23: Sıcak Eriyik Ekstrüzyon Teknolojisi İle Posakonazol Etken Maddesinin Çözünürlüğünü Artırmak İçin Hidrofilik Polimerlerin Kullanımı | F23: Ayla AKINCIOĞLU | G23: 58141431030 | H23: ayla_minaz@hotmail.com | I23: (0543) 420-8559 | J23: 41459 | K23: Kabul Edildi | L23: Doç. Dr. Mehmet Murat ÖZMEN | M23: Var | N23: 0 | O23: 0 | P23: 0 | Q23: 0 | R23: 1 | S23: 0
A24: 13505035 | B24: Tezli Yüksek Lisans | C24: Elektronik ve Haberleşme Müh. | D24: Haberleşme | E24: Renk Özelliği Kullanılmadan Nesne Hareket Tespiti Ve Görüntü İşleme İle Nesne Takibi | F24: Mehmet UZUN | G24: 25795800994 | H24: uzunmehmet1988@hotmail.com | I24: (0539) 838-6708 | J24: 43348 | K24: Kabul Edildi | L24: Dr. Öğr. Üyesi Lale ÖZYILMAZ | M24: Var | N24: 0 | O24: 0 | P24: 0 | Q24: 0 | R24: 0 | S24: 1
A25: 15520062 | B25: Tezli Yüksek Lisans | C25: Kimya Müh. | D25: Kimya Müh. | E25: Çoklu Döküm Alçı Kalıp Karakterizasyonu Ve Kurutma Parametrelerinin Belirlenmesi | F25: Erman LEVENT TEMELKURAN | G25: 52207121088 | H25: leventtemelkuran@gmail.com | I25: (0535) 899-2001 | J25: 42401 | K25: Kabul Edildi | L25: Doç. Dr. Yasemen Kalpaklı | M25: Var | N25: 0 | O25: 0 | P25: 0 | Q25: 0 | R25: 1 | S25: 0
A26: 14554034 | B26: Doktora | C26: Biyomühendislik | D26: Biyomühendislik | E26: Kısa, Orta Ve Uzun Dönem Kan Şeker Ölçümlerini Eş Zamanlı Gerçekleştiren Yeni Bir Ölçüm Yöntemi Geliştirilmesi | F26: Duygu ÜNER BAHAR | G26: 45043527886 | H26: duygu.uner1@gmail.com | I26: (0530) 222-9144 | J26: 42037 | K26: Kabul Edildi | L26: Prof. Dr. İbrahim IŞILDAK | M26: Var | N26: 0 | O26: 0 | P26: 0 | Q26: 0 | R26: 0 | S26: 1
A27: 13508011 | B27: Doktora | C27: Gemi İnşaatı ve Gemi Mak. Müh. | D27: Gemi İnşaatı ve Gemi Mak. Müh. | E27: Enerji Sistemlerinin Performans Ve Boyut Optimizasyonu: Yapısal Gelişim Teorisi | F27: Ümit GÜNEŞ | G27: 57994375706 | H27: umitgunes87@gmail.com | I27: (0506) 558-8033 | J27: 41519 | K27: Kabul Edildi | L27: Prof. Dr. Bahri Şahin | M27: Var | N27: 0 | O27: 0 | P27: 0 | Q27: 0 | R27: 0 | S27: 1
A28: 15567023 | B28: Tezli Yüksek Lisans | C28: Elektrik Müh. | D28: Elektrik Müh - Kontrol ve Otomasyon | E28: Dört Rotorlu Hava Araçlarıiçin Doğrusal Olmayan Kontrol Yöntemlerinin İncelenmesi | F28: Fahed SAYED | G28: 42299170958 | H28: fahed0999@gmail.com | I28: (0531) 610-5141 | J28: 42265 | K28: Kabul Edildi | L28: Dr. Öğr. Üyesi Türker Türker | M28: Var | N28: 0 | O28: 0 | P28: 0 | Q28: 0 | R28: 1 | S28: 0
A29: 12524003 | B29: Tezli Yüksek Lisans | C29: Makine Müh. | D29: Konstrüksiyon | E29: Mekanik Dübellerin Dinamik Yük Etkiler Altında Yapısal Olarak İncelenmesi | F29: Gökhan SAMET KORKMAZ | G29: 17431614782 | H29: gokhansametkorkmaz@gmail.com | I29: (0505) 805-5871 | J29: 41163 | K29: Kabul Edildi | L29: Dr. Öğr. Üyesi BERNA BOLAT | M29: Yok | N29: 0 | O29: 0 | P29: 0 | Q29: 0 | R29: 0 | S29: 0
A30: 13550016 | B30: Tezli Yüksek Lisans | C30: Harita Müh. | D30: Uzaktan Algılama ve CBS | E30: Openstreetmap Verilerindeki Bina Çokgenlerinin Büyük Ölçekli Topografik Harita Verileri İle Karşılaştırmalı Geometrik Kalite Analizi | F30: Özge ECE ERDEN | G30: 31084089766 | H30: zgeece.erden@gmail.com | I30: (0506) 941-5144 | J30: 41520 | K30: Kabul Edildi | L30: Prof. Dr. Ali Melih Başaraner | M30: Var | N30: 0 | O30: 0 | P30: 0 | Q30: 0 | R30: 1 | S30: 0
A31: 13549007 | B31: Tezli Yüksek Lisans | C31: Elektrik Müh. | D31: Elektrik Tesisleri | E31: Nesnelerin Internetinde Kullanılan Haberleşme Protokollerinde Emniyet | F31: İsmail KARADEMİR | G31: 25043177458 | H31: i.karademir@yandex.com | I31: (0537) 394-9882 | J31: 41459 | K31: Kabul Edildi | L31: Dr. Öğr. Üyesi Janset Daşdemir | M31: Var | N31: 0 | O31: 0 | P31: 0 | Q31: 0 | R31: 1 | S31: 0
A32: 12568106 | B32: Tezli Yüksek Lisans | C32: Mekatronik Müh. | D32: Mekatronik Müh. | E32: İnsansız Hava Araçlarında Kontrol Uygulamaları | F32: Caner ÇOPUR | G32: 10313510318 | H32: canercopur59@hotmail.com | I32: (0532) 765-6548 | J32: 41317 | K32: Kabul Edildi | L32: Prof. Dr. Vasfi Emre ÖMÜRLÜ | M32: Var | N32: 0 | O32: 0 | P32: 0 | Q32: 0 | R32: 1 | S32: 0
A33: 15520043 | B33: Tezli Yüksek Lisans | C33: Kimya Müh. | D33: Kimya Müh. | E33: Nanoselüloz Dolgulu Sodyum Aljinat/Polivinil Alkol Matrisli Membranların Hazırlanması Karakterizasyonu Ve Alkol Su Karışımlarını Ayırma Performansının İncelenmesi | F33: Ali BEKİR SEVER | G33: 36265116774 | H33: alibekirsever@hotmail.com | I33: (0536) 568-7905 | J33: 42389 | K33: Taslak | L33: Dr. Öğr. Üyesi İlknur KÜÇÜK | M33: Var | N33: 0 | O33: 0 | P33: 0 | Q33: 0 | R33: 1 | S33: 0
... A69: 15555015 | B69: Tezli Yüksek Lisans | C69: Elektrik Müh. | D69: Elektrik Mak. ve Güç Elektroniği | E69: Led Sürücü Devresinin Tasarım Ve Simülasyonu | F69: Murat TUNCER | G69: 28528063598 | H69: murattunceriu@gmail.com | I69: (0506) 394-4516 | J69: 42247 | K69: Kabul Edildi | L69: Dr. Öğr. Üyesi Burak AKIN | M69: Var | N69: 0 | O69: 0 | P69: 0 | Q69: 0 | R69: 1 | S69: 0
A70: F0715035 | B70: Tezli Yüksek Lisans | C70: Fizik | D70: Fizik | E70: Kimyasal Püskürtme Yöntemiyle Homojenliği Arttıracak Sisleştirici/Püskürtme Odacık Sisteminin Geliştirilmesi Ve Farklı Malzemelerde Uygulanması | F70: Melıs ÖZŞAHİN | G70: 10675401644 | H70: melis_ozsahin@hotmail.com | I70: (0533) 622-2988 | J70: 42394 | K70: Kabul Edildi | L70: Prof. Dr. Orhan İÇELLİ | M70: Var | N70: 0 | O70: 0 | P70: 0 | Q70: 0 | R70: 1 | S70: 0
A71: 16508012 | B71: Tezli Yüksek Lisans | C71: Gemi İnşaatı ve Gemi Mak. Müh. | D71: Gemi İnşaatı ve Gemi Mak. Müh. | E71: Yat Tasarımı Ve Üretimde 3D Printer Kullanımı | F71: Şükrü ORÇUN TAŞ | G71: 26560019368 | H71: orcunsukru@gmail.com | I71: (0506) 650-8100 | J71: 42585 | K71: Kabul Edildi | L71: Dr. Öğr. Üyesi Bekir ŞENER | M71: Var | N71: 0 | O71: 0 | P71: 0 | Q71: 0 | R71: 1 | S71: 0
A72: 10501205 | B72: Doktora | C72: Bilgisayar Müh. | D72: Bilgisayar Müh. | E72: Nöropatik Ağrı Tanı Ve Tedavisinde Kullanılacak Kortıkal Ölçev Sistemının Donanım Olarak Gerçeklenmesi | F72: Coşkun KAZMA | G72: 18964955298 | H72: coskun.kazma@gmail.com | I72: (0533) 562-7819 | J72: 40445 | K72: Kabul Edildi | L72: Prof. Dr. Nizamettin Aydın | M72: Var | N72: 0 | O72: 0 | P72: 0 | Q72: 0 | R72: 1 | S72: 0
A73: 14557004 | B73: Tezli Yüksek Lisans | C73: Şehir ve Bölge Planlama | D73: Şehir Planlama | E73: Kentsel Dönüşümde Örgütlenme Kapasitesinin Kentsel Rekabet Gücüne Etkisi "Bayrampaşa Eski Cezaevi Kentsel Dönüşüm Projesi Örneği" | F73: Samettin MURAT AYAN | G73: 39545147918 | H73: murat.ayan257@gmail.com | I73: (0507) 287-6148 | J73: 41828 | K73: İptal Edildi | L73: Dr. Öğr. Üyesi Ercan KOÇ | M73: Var | N73: 0 | O73: 0 | P73: 1 | Q73: 0 | R73: 0 | S73: 0
A74: 13533007 | B74: Tezli Yüksek Lisans | C74: Mimarlık | D74: Mimarlık Tarihi ve Kuramı | E74: Iı. Abdülhamid Dönemi İtibarıyla Kentsel Modernleşme Hareketleri Ve Değişen İstanbul Düzeni | F74: Sümeyye ŞURA YÜCEL | G74: 21709188196 | H74: ssura19@hotmail.com | I74: (0554) 433-5860 | J74: 41459 | K74: Kabul Edildi | L74: Dr. Öğr. Üyesi Zafer SAĞDIÇ | M74: Var | N74: 0 | O74: 0 | P74: 0 | Q74: 0 | R74: 1 | S74: 0
A75: 15523020 | B75: Tezli Yüksek Lisans | C75: Makine Müh. | D75: İmal Usulleri | E75: Alüminyum Ekstrüzyon Profillerinde Görülen Hataların Analizi | F75: Utku DEMİR | G75: 35737056006 | H75: utkudemir134@gmail.com | I75: (0555) 205-3366 | J75: 42391 | K75: Kabul Edildi | L75: Prof. Dr. Ayşegül AKDOĞAN EKER | M75: Var | N75: 0 | O75: 0 | P75: 0 | Q75: 0 | R75: 1 | S75: 0
...

Sheet YL Jüri
A1: Bu tabloda | B1: 11558004 | C1: nolu öğrenci bilgileri getirilmiştir
A3: Öğrenci No: | B3: Öğrenci Adı-Soyadı: | C3: Ana Bilim Dalı | D3: Programı
A4: =VLOOKUP(B1,BasvuruListesi!A:S,1,0) -> 11558004 | B4: =VLOOKUP(B1,BasvuruListesi!A:S,6,0) -> Merve NUR GÜNEN | C4: =VLOOKUP(B1,BasvuruListesi!A:S,3,0) -> Şehir ve Bölge Planlama | D4: =VLOOKUP(B1,BasvuruListesi!A:K,4,0) -> Kentsel Mekan Organizasyon - Tasarım
A5: Gsis Kayıt Tarihi: | B5: =VLOOKUP(B1,BasvuruListesi!A:S,10,0) -> 40806
A6: Yayın Şartı | B6: =VLOOKUP(B1,BasvuruListesi!A:S,13,0) -> Yok
A7: Yayın | B7: =IF((VLOOKUP(B1,BasvuruListesi!A:S,14,0))>0, "PATENT", IF(VLOOKUP(B1,BasvuruListesi!A:S,15,0)>0,"PROJE", IF(VLOOKUP(B1,BasvuruListesi!A:S,16,0)>0,"UL Bildiri", IF(VLOOKUP(B1,BasvuruListesi!A:S,17,0)>0,"UL Makale", IF(VLOOKUP(B1,BasvuruListesi!A:S,18,0)>0,"UA Bildiri", IF(VLOOKUP(B1,BasvuruListesi!A:S,19,0)>0,"UA Makale","Yayın YOK" )))))) -> Yayın YOK
A8: Tez Başlığı (Online Sistem) | B8: =VLOOKUP(B1,BasvuruListesi!A:S,5,0) -> Tarihi Kent Dokusunda Kamusal Alan Tasarımı Bursa Hanlar Bölgesi Örneğinde Uygulanabirliğinin İncelenmesi
A9: Tez Başlığı(GSİS) | B9: Tarihi Kent Dokusunda Kamusal Alan Tasarımı Bursa Hanlar Bölgesi Örneğinde Uygulanabirliğinin İncelenmesi
A10: Danışman Adı-Soyadı: | B10: =VLOOKUP(B1,BasvuruListesi!A:S,12,0) -> Doç. Dr. N. HÜLYA BERKMEN
A11: Kurum İçi | B11: Unvan | C11: Ad-Soyad | D11: Ana Bilim Dalı
A12: Jüri-1 | B12: Doç. Dr. | C12: Cemal Cenk HAMAMCIOĞLU | D12: =VLOOKUP(Table1[[#This Row],[Ad-Soyad]],JuriKurumici!A1:D894,4) -> SEHİR BÖLGE PLAN.BÖL
A13: Jüri-2 | B13: =VLOOKUP(Table1[[#This Row],[Ad-Soyad]],JuriKurumici!A:D,2,0) -> Dr.Öğr.Üyesi | C13: Ali KILIÇ | D13: =VLOOKUP(Table1[[#This Row],[Ad-Soyad]],JuriKurumici!A1:D894,4) -> SEHİR BÖLGE PLAN.BÖL
A14: Jüri-3 | B14: =VLOOKUP(Table1[[#This Row],[Ad-Soyad]],JuriKurumici!A:D,2,0) -> Doç.Dr. | C14: Esin Özlem AKTUĞLU AKTAN | D14: =VLOOKUP(Table1[[#This Row],[Ad-Soyad]],JuriKurumici!A1:D894,4) -> SEHİR BÖLGE PLAN.BÖL
A15: Jüri-4 | B15: =VLOOKUP(Table1[[#This Row],[Ad-Soyad]],JuriKurumici!A:D,2,0) -> #N/A | D15: =VLOOKUP(Table1[[#This Row],[Ad-Soyad]],JuriKurumici!A1:D894,3,0) -> #N/A
A16: Kurum Dışı | B16: Unvan | C16: Ad-Soyad | D16: Ana Bilim Dalı
A17: Jüri-1 | B17: Doç. Dr. | C17: Pelin Pınar GİRİTLİOĞLU | D17: İÜ
A18: Jüri-2 | B18: Doç. Dr. | C18: Cem BEYGO | D18: İÜ
A19: Jüri-3 | B19: Dr. Öğr. Üyesi | C19: Dilek Erden ERBEY | D19: MSGSU
A20: Jüri-4 | B20: Doç. Dr. | C20: A. Erdem ERBAŞ | D20: MSGSU
D21: =VLOOKUP(Table1[Unvan],JuriKurumici!A:D,4,0) -> #N/A

Sheet YL Mezuniyet
A1: Bu tabloda | B1: 16504021 | C1: nolu öğrenci bilgileri getirilmiştir
A3: Öğrenci No: | B3: Adı-Soyadı: | C3: Ana Bilim Dalı | D3: Programı
A4: =VLOOKUP(B1,BasvuruListesi!A:S,1,0) -> 16504021 | B4: =VLOOKUP(B1,BasvuruListesi!A:S,6,0) -> Yunus EMRE FEDAR | C4: =VLOOKUP(B1,BasvuruListesi!A:S,3,0) -> Elektronik ve Haberleşme Müh. | D4: =VLOOKUP(B1,BasvuruListesi!A:K,4,0) -> Elektronik
A5: Tez Danışmanı: | B5: =VLOOKUP(B1,BasvuruListesi!A:S,12,0) -> Prof. Dr. Herman SEDEF
A6: Tez Başlığı: | B6: =VLOOKUP(B1,BasvuruListesi!A:S,5,0) -> Gelişmiş Mikrodenetleyici Kontrollü Akıllı Ev Otomasyonu
A7: Savunma Tarihi:
A8: Tez Teslim Tarihi:
A9: Gsis Kayıt Tarihi: | B9: =VLOOKUP(B1,BasvuruListesi!A:S,10,0) -> 42614
A10: Yayın Şartı: | B10: =VLOOKUP(B1,BasvuruListesi!A:S,13,0) -> Var
A11: Yayın: | B11: =IF((VLOOKUP(B1,BasvuruListesi!A:S,14,0))>0, "PATENT", IF(VLOOKUP(B1,BasvuruListesi!A:S,15,0)>0,"PROJE", IF(VLOOKUP(B1,BasvuruListesi!A:S,16,0)>0,"UL Bildiri", IF(VLOOKUP(B1,BasvuruListesi!A:S,17,0)>0,"UL Makale", IF(VLOOKUP(B1,BasvuruListesi!A:S,18,0)>0,"UA Bildiri", IF(VLOOKUP(B1,BasvuruListesi!A:S,19,0)>0,"UA Makale","Yayın YOK" )))))) -> UL Bildiri
A12: Durum: | B12: OYBİRLİĞİ/BAŞARILI

Sheet DR Jüri
A1: Bu tabloda | B1: 15549018 | C1: nolu öğrenci bilgileri getirilmiştir
A3: Öğrenci No: | B3: Öğrenci Adı-Soyadı: | C3: Ana Bilim Dalı | D3: Programı
A4: =VLOOKUP(B1,BasvuruListesi!A:S,1,0) -> 15549018 | B4: =VLOOKUP(B1,BasvuruListesi!A:S,6,0) -> İsmail CEM AÇIKGÖZ | C4: =VLOOKUP(B1,BasvuruListesi!A:S,3,0) -> Elektrik Müh. | D4: =VLOOKUP(B1,BasvuruListesi!A:K,4,0) -> Elektrik Tesisleri
A5: Gsis Kayıt Tarihi: | B5: =VLOOKUP(B1,BasvuruListesi!A:S,10,0) -> 42191
A6: Yayın Şartı | B6: =VLOOKUP(B1,BasvuruListesi!A:S,13,0) -> Var
A7: Yayın | B7: =IF((VLOOKUP(B1,BasvuruListesi!A:S,14,0))>0, "PATENT", IF(VLOOKUP(B1,BasvuruListesi!A:S,15,0)>0,"PROJE", IF(VLOOKUP(B1,BasvuruListesi!A:S,16,0)>0,"UL Bildiri", IF(VLOOKUP(B1,BasvuruListesi!A:S,17,0)>0,"UL Makale", IF(VLOOKUP(B1,BasvuruListesi!A:S,18,0)>0,"UA Bildiri", IF(VLOOKUP(B1,BasvuruListesi!A:S,19,0)>0,"UA Makale","Yayın YOK" )))))) -> UA Bildiri
A8: Tez Başlığı (Online Sistem) | B8: =VLOOKUP(B1,BasvuruListesi!A:S,5,0) -> Volan Ve Lı-Ion Batarya Enerji Depolama Sistemlerinin Kıyaslanması Ve Hibrit Enerji Depolama Sisteminin Farklı Yük Profilleri Üzerinde Performans Analizi
A9: Tez Başlığı(GSİS) | B9: Mikroşebekelerde Enerji Depolama Teknolojilerinin Ekonomik ve Performans Analizi
A10: Danışman Adı-Soyadı: | B10: =VLOOKUP(B1,BasvuruListesi!A:S,12,0) -> Dr. Öğr. Üyesi Mustafa BAYSAL
A11: TİK-1 (Kurum İçi)
A12: TİK-2 (Kurum Dışı)
A13: Kurum İçi | B13: Unvan | C13: Ad-Soyad | D13: Ana Bilim Dalı
A14: Jüri-1 | B14: =VLOOKUP(Table14[[#This Row],[Ad-Soyad]],JuriKurumici!A:D,2,0) -> Dr.Öğr.Üyesi | C14: Bedri KEKEZOĞLU | D14: =VLOOKUP(Table14[[#This Row],[Ad-Soyad]],JuriKurumici!A1:D894,4) -> ELEKTRİK MÜH.
A15: Jüri-2 | B15: =VLOOKUP(Table14[[#This Row],[Ad-Soyad]],JuriKurumici!A:D,2,0) -> Dr.Öğr.Üyesi | C15: Altuğ BOZKURT | D15: =VLOOKUP(Table14[[#This Row],[Ad-Soyad]],JuriKurumici!A1:D894,4) -> ELEKTRİK MÜH.
A16: Jüri-3 | B16: =VLOOKUP(Table14[[#This Row],[Ad-Soyad]],JuriKurumici!A:D,2,0) -> Dr.Öğr.Üyesi | C16: Oktay ARIKAN | D16: =VLOOKUP(Table14[[#This Row],[Ad-Soyad]],JuriKurumici!A1:D894,4) -> ELEKTRİK MÜH.
A17: Jüri-4 | B17: =VLOOKUP(Table14[[#This Row],[Ad-Soyad]],JuriKurumici!A:D,2,0) -> Doç.Dr. | C17: Recep YUMURTACI | D17: =VLOOKUP(Table14[[#This Row],[Ad-Soyad]],JuriKurumici!A1:D894,3,0) -> ELEKTRİK- ELEK. FAKÜLTESİ
A18: Kurum Dışı | B18: Unvan | C18: Ad-Soyad | D18: Üniversite Adı
A19: Jüri-1 | B19: Dr.Öğr.Üyesi | C19: Hakan AKÇA | D19: Gelişim Üni.
A20: Jüri-2 | B20: Dr.Öğr. Üyesi | C20: Abdulfetah SHOBOLE | D20: İZÜ
A21: Jüri-3 | B21: Dr.Öğr. Üyesi | C21: Oğuzhan CEYLAN | D21: Kadir Has Üni.
A22: Jüri-4 | B22: Dr.Öğr. Üyesi | C22: Mohammed WADI | D22: İZÜ

Sheet DR Mezuniyet
A1: Bu tabloda | B1: 16504021 | C1: nolu öğrenci bilgileri getirilmiştir
A3: Öğrenci No: | B3: Adı-Soyadı: | C3: Ana Bilim Dalı | D3: Programı
A4: =VLOOKUP(B1,BasvuruListesi!A:S,1,0) -> 16504021 | B4: =VLOOKUP(B1,BasvuruListesi!A:S,6,0) -> Yunus EMRE FEDAR | C4: =VLOOKUP(B1,BasvuruListesi!A:S,3,0) -> Elektronik ve Haberleşme Müh. | D4: =VLOOKUP(B1,BasvuruListesi!A:K,4,0) -> Elektronik
A5: Tez Danışmanı: | B5: =VLOOKUP(B1,BasvuruListesi!A:S,12,0) -> Prof. Dr. Herman SEDEF
A6: Tez Başlığı: | B6: =VLOOKUP(B1,BasvuruListesi!A:S,5,0) -> Gelişmiş Mikrodenetleyici Kontrollü Akıllı Ev Otomasyonu
A7: Savunma Tarihi:
A8: Tez Teslim Tarihi:
A9: Gsis Kayıt Tarihi: | B9: =VLOOKUP(B1,BasvuruListesi!A:S,10,0) -> 42614
A10: Yayın Şartı: | B10: =VLOOKUP(B1,BasvuruListesi!A:S,13,0) -> Var
A11: Yayın: | B11: =IF((VLOOKUP(B1,BasvuruListesi!A:S,14,0))>0, "PATENT", IF(VLOOKUP(B1,BasvuruListesi!A:S,15,0)>0,"PROJE", IF(VLOOKUP(B1,BasvuruListesi!A:S,16,0)>0,"UL Bildiri", IF(VLOOKUP(B1,BasvuruListesi!A:S,17,0)>0,"UL Makale", IF(VLOOKUP(B1,BasvuruListesi!A:S,18,0)>0,"UA Bildiri", IF(VLOOKUP(B1,BasvuruListesi!A:S,19,0)>0,"UA Makale","Yayın YOK" )))))) -> UL Bildiri
A12: Durum: | B12: OYBİRLİĞİ/BAŞARILI
